Workbook

Sheet BESOIN EN EAU
B1: Localisation Gabes | C1: Valeur des ET0 mensuelles mm
C2: Janvier | D2: Fevrier | E2: Mars | F2: Avril | G2: Mai | H2: Juin | I2: Juillet | J2: Août | K2: Septembre | L2: Octobre | M2: Novembre | N2: Decembre
B3: NOMBRE DE JOURS | C3: 31 | D3: 28 | E3: 31 | F3: 30 | G3: 31 | H3: 30 | I3: 31 | J3: 31 | K3: 30 | L3: 31 | M3: 30 | N3: 31
B4: ET0 MOIS (mm) | C4: 64.8 | D4: 51.8 | E4: 75.4 | F4: 98.8 | G4: 145.2 | H4: 179.2 | I4: 231.5 | J4: 233 | K4: 161.4 | L4: 122.1 | M4: 73.1 | N4: 48.9
B5: ET0 JOURS (mm) | C5: =C4/C3 -> 2.0903226 | D5: =D4/D3 -> 1.85 | E5: =E4/E3 -> 2.4322581 | F5: =F4/F3 -> 3.2933333 | G5: =G4/G3 -> 4.683871 | H5: =H4/H3 -> 5.9733333 | I5: =I4/I3 -> 7.4677419 | J5: =J4/J3 -> 7.516129 | ... N5: =N4/N3 -> 1.5774194
B6: PLUIE MOYENNE | C6: 0 | D6: 0 | E6: 0 | F6: 0 | G6: 0 | H6: 0 | I6: 0 | J6: 0 | K6: 0 | L6: 0 | M6: 0 | N6: 0
A7: Peff=Pm*0,7 | B7: PLUIE EFFICACE 70% | C7: =C6*0.7 -> 0 | D7: =D6*0.7 -> 0 | E7: =E6*0.7 -> 0 | F7: =F6*0.7 -> 0 | G7: =G6*0.7 -> 0 | H7: =H6*0.7 -> 0 | I7: =I6*0.7 -> 0 | J7: =J6*0.7 -> 0 | ... N7: =N6*0.7 -> 0
B8: EFFICIENCE Ea=90% | C8: 0.9 | D8: 0.9 | E8: 0.9 | F8: 0.9 | G8: 0.9 | H8: 0.9 | I8: 0.9 | J8: 0.9 | K8: 0.9 | L8: 0.9 | M8: 0.9 | N8: 0.9
B10: Kc | C10: 0.3 | D10: 0.4 | E10: 0.4 | F10: 0.5 | G10: 0.8 | H10: 1 | I10: 1.05 | J10: 1.05 | K10: 1.05 | L10: 1 | M10: 1 | N10: 0.8
B11: Kr | C11: 0.7 | D11: 0.7 | E11: 0.7 | F11: 0.7 | G11: 0.7 | H11: 0.7 | I11: 0.7 | J11: 0.7 | K11: 0.7 | L11: 0.7 | M11: 0.7 | N11: 0.7
A12: Be net= Kc * Kr * ET0 jours | B12: Be Net (mm) | C12: =C11*C10*C5 -> 0.43896774 | D12: =D11*D10*D5 -> 0.518 | E12: =E11*E10*E5 -> 0.68103226 | F12: =F11*F10*F5 -> 1.1526667 | G12: =G11*G10*G5 -> 2.6229677 | H12: =H11*H10*H5 -> 4.1813333 | I12: =I11*I10*I5 -> 5.4887903 | J12: =J11*J10*J5 -> 5.5243548 | ... N12: =N11*N10*N5 -> 0.88335484
A13: Be brut= Be net*Efficie,nce | B13: Be Brut (mm) | C13: =C12*C8 -> 0.39507097 | D13: =D12*D8 -> 0.4662 | E13: =E12*E8 -> 0.61292903 | F13: =F12*F8 -> 1.0374 | G13: =G12*G8 -> 2.360671 | H13: =H12*H8 -> 3.7632 | I13: =I12*I8 -> 4.9399113 | J13: =J12*J8 -> 4.9719194 | ... N13: =N12*N8 -> 0.79501935
B14: Be Brut-Pluie efficace | C14: =C5-(C7/C3) -> 2.0903226 | D14: =D5-(D7/D3) -> 1.85 | E14: =E5-(E7/E3) -> 2.4322581 | F14: =F5-(F7/F3) -> 3.2933333 | G14: =G5-(G7/G3) -> 4.683871 | H14: =H5-(H7/H3) -> 5.9733333 | I14: =I5-(I7/I3) -> 7.4677419 | J14: =J5-(J7/J3) -> 7.516129 | ... N14: =N5-(N7/N3) -> 1.5774194
B15: Be Brutt m3/ha | C15: =C13*10 -> 3.9507097 | D15: =D13*10 -> 4.662 | E15: =E13*10 -> 6.1292903 | F15: =F13*10 -> 10.374 | G15: =G13*10 -> 23.60671 | H15: =H13*10 -> 37.632 | I15: =I13*10 -> 49.399113 | J15: =J13*10 -> 49.719194 | ... N15: =N13*10 -> 7.9501935
B16: Superficie | C16: 5 | D16: 5 | E16: 5 | F16: 5 | G16: 5 | H16: 5 | I16: 5 | J16: 5 | K16: 5 | L16: 5 | M16: 5 | N16: 5
B17: Be Brut m3/mois | C17: =C16*C15*C3 -> 612.36 | D17: =D16*D15*D3 -> 652.68 | E17: =E16*E15*E3 -> 950.04 | F17: =F16*F15*F3 -> 1556.1 | G17: =G16*G15*G3 -> 3659.04 | H17: =H16*H15*H3 -> 5644.8 | I17: =I16*I15*I3 -> 7656.8625 | J17: =J16*J15*J3 -> 7706.475 | ... N17: =N16*N15*N3 -> 1232.28 | O17: =SUM(C17:N17) -> 41157.743
B19: Besoins totaux | C19: =C17 -> 612.36 | D19: =D17 -> 652.68 | E19: =E17 -> 950.04 | F19: =F17 -> 1556.1 | G19: =G17 -> 3659.04 | H19: =H17 -> 5644.8 | I19: =I17 -> 7656.8625 | J19: =J17 -> 7706.475 | ... N19: =N17 -> 1232.28 | O19: =SUM(C19:N19) -> 41157.743
B20: Besoins en eau réel | C20: =C19-(C16*C7*10) -> 612.36 | D20: =D19-(D16*D7*10) -> 652.68 | E20: =E19-(E16*E7*10) -> 950.04 | F20: =F19-(F16*F7*10) -> 1556.1 | G20: =G19-(G16*G7*10) -> 3659.04 | H20: =H19-(H16*H7*10) -> 5644.8 | I20: =I19-(I16*I7*10) -> 7656.8625 | J20: =J19-(J16*J7*10) -> 7706.475 | ... N20: =N19-(N16*N7*10) -> 1232.28 | O20: =SUM(C20:N20) -> 41157.743
B21: Q forage l/s | C21: =4*3.6 -> 14.4 | D21: =4*3.6 -> 14.4 | E21: =4*3.6 -> 14.4 | F21: =4*3.6 -> 14.4 | G21: =4*3.6 -> 14.4 | H21: =4*3.6 -> 14.4 | I21: =4*3.6 -> 14.4 | J21: =4*3.6 -> 14.4 | ... N21: =4*3.6 -> 14.4
B22: Nbre heures Fonctionnement | C22: =(C20/C21)/C3 -> 1.3717742 | D22: =(D20/D21)/D3 -> 1.61875 | E22: =(E20/E21)/E3 -> 2.1282258 | F22: =(F20/F21)/F3 -> 3.6020833 | G22: =(G20/G21)/G3 -> 8.1967742 | H22: =(H20/H21)/H3 -> 13.066667 | I22: =(I20/I21)/I3 -> 17.15247 | J22: =(J20/J21)/J3 -> 17.263609 | ... N22: =(N20/N21)/N3 -> 2.7604839
B23: Volume disponible | C23: =C22*C21*C3 -> 612.36 | D23: =D22*D21*D3 -> 652.68 | E23: =E22*E21*E3 -> 950.04 | F23: =F22*F21*F3 -> 1556.1 | G23: =G22*G21*G3 -> 3659.04 | H23: =H22*H21*H3 -> 5644.8 | I23: =I22*I21*I3 -> 7656.8625 | J23: =J22*J21*J3 -> 7706.475 | ... N23: =N22*N21*N3 -> 1232.28
B24: Bilan ressource-besoin reel | C24: =C23-C20 -> 0 | D24: =D23-D20 -> 0 | E24: =E23-E20 -> 0 | F24: =F23-F20 -> 0 | G24: =G23-G20 -> 0 | H24: =H23-H20 -> 0 | I24: =I23-I20 -> 0 | J24: =J23-J20 -> 0 | ... N24: =N23-N20 -> 0
B28: ETC=ETR*Kc
C30: Janvier | D30: Fevrier | E30: Mars | F30: Avril | G30: Mai | H30: Juin | I30: Juillet | J30: Août | K30: Septembre | L30: Octobre | M30: Novembre | N30: Decembre
B31: NOMBRE DE JOURS | C31: 31 | D31: 28 | E31: 31 | F31: 30 | G31: 31 | H31: 30 | I31: 31 | J31: 31 | K31: 30 | L31: 31 | M31: 30 | N31: 31
B32: ET0 JOURS mm | C32: 1.5064516 | D32: 1.85 | E32: 2.4322581 | F32: 3.2933333 | G32: 4.683871 | H32: 5.9733333 | I32: 7.4677419 | J32: 7.516129 | K32: 5.38 | L32: 3.9387097 | M32: 2.4366667 | N32: 1.5774194
B33: ET0 JOURS m3/ha | C33: =C32*10 -> 15.064516 | D33: =D32*10 -> 18.5 | E33: =E32*10 -> 24.322581 | F33: =F32*10 -> 32.933333 | G33: =G32*10 -> 46.83871 | H33: =H32*10 -> 59.733333 | I33: =I32*10 -> 74.677419 | J33: =J32*10 -> 75.16129 | ... N33: =N32*10 -> 15.774194
B34: ET0 MOIS mm | C34: =C32*C31 -> 46.7 | D34: =D32*D31 -> 51.8 | E34: =E32*E31 -> 75.4 | F34: =F32*F31 -> 98.8 | G34: =G32*G31 -> 145.2 | H34: =H32*H31 -> 179.2 | I34: =I32*I31 -> 231.5 | J34: =J32*J31 -> 233 | ... N34: =N32*N31 -> 48.9
B35: ET0 MOIS m3/ha | C35: =C34*10 -> 467 | D35: =D34*10 -> 518 | E35: =E34*10 -> 754 | F35: =F34*10 -> 988 | G35: =G34*10 -> 1452 | H35: =H34*10 -> 1792 | I35: =I34*10 -> 2315 | J35: =J34*10 -> 2330 | ... N35: =N34*10 -> 489
B37: Kc | C37: 0.1 | D37: 0.1 | E37: 0.15 | F37: 0.2 | G37: 0.2 | H37: 0.25 | I37: 0.3 | J37: 0.3 | K37: 0.25 | L37: 0.2 | M37: 0.15 | N37: 0.1
B38: Kr | C38: 0.36 | D38: 0.36 | E38: 0.36 | F38: 0.36 | G38: 0.36 | H38: 0.36 | I38: 0.36 | J38: 0.36 | K38: 0.36 | L38: 0.36 | M38: 0.36 | N38: 0.36
B39: Superficie | C39: 16 | D39: =C39 -> 16 | E39: =D39 -> 16 | F39: =E39 -> 16 | G39: =F39 -> 16 | H39: =G39 -> 16 | I39: =H39 -> 16 | J39: =I39 -> 16 | K39: =J39 -> 16 | ... N39: =M39 -> 16
B40: EFFICIENCE Ea=90% | C40: 0.9 | D40: 0.9 | E40: 0.9 | F40: 0.9 | G40: 0.9 | H40: 0.9 | I40: 0.9 | J40: 0.9 | K40: 0.9 | L40: 0.9 | M40: 0.9 | N40: 0.9
B41: Be Brut (m3) | C41: =(C35*C37*C38*C39)/C40 -> 298.88 | D41: =(D35*D37*D38*D39)/D40 -> 331.52 | E41: =(E35*E37*E38*E39)/E40 -> 723.84 | F41: =(F35*F37*F38*F39)/F40 -> 1264.64 | G41: =(G35*G37*G38*G39)/G40 -> 1858.56 | H41: =(H35*H37*H38*H39)/H40 -> 2867.2 | I41: =(I35*I37*I38*I39)/I40 -> 4444.8 | J41: =(J35*J37*J38*J39)/J40 -> 4473.6 | ... N41: =(N35*N37*N38*N39)/N40 -> 312.96 | O41: =SUM(C41:N41) -> 21423.04
B43: Kc | C43: 0.1 | D43: 0.1 | E43: 0.15 | F43: 0.2 | G43: 0.2 | H43: 0.25 | I43: 0.3 | J43: 0.3 | K43: 0.25 | L43: 0.2 | M43: 0.15 | N43: 0.1
B44: Kr | C44: 0.5 | D44: 0.5 | E44: 0.5 | F44: 0.5 | G44: 0.5 | H44: 0.5 | I44: 0.5 | J44: 0.5 | K44: 0.5 | L44: 0.5 | M44: 0.5 | N44: 0.5
B45: Superficie | C45: 1 | D45: 1 | E45: 1 | F45: 1 | G45: 1 | H45: 1 | I45: 1 | J45: 1 | K45: 1 | L45: 1 | M45: 1 | N45: 1
B46: EFFICIENCE Ea=90% | C46: 0.9 | D46: 0.9 | E46: 0.9 | F46: 0.9 | G46: 0.9 | H46: 0.9 | I46: 0.9 | J46: 0.9 | K46: 0.9 | L46: 0.9 | M46: 0.9 | N46: 0.9
B47: Be Brut (m3) | C47: =(C45*C44*C43*C35)/C46 -> 25.944444 | D47: =(D45*D44*D43*D35)/D46 -> 28.777778 | E47: =(E45*E44*E43*E35)/E46 -> 62.833333 | F47: =(F45*F44*F43*F35)/F46 -> 109.77778 | G47: =(G45*G44*G43*G35)/G46 -> 161.33333 | H47: =(H45*H44*H43*H35)/H46 -> 248.88889 | I47: =(I45*I44*I43*I35)/I46 -> 385.83333 | J47: =(J45*J44*J43*J35)/J46 -> 388.33333 | ... N47: =(N45*N44*N43*N35)/N46 -> 27.166667 | O47: =SUM(C47:N47) -> 1859.6389
B49: Kc | C49: 0.1 | D49: 0.1 | E49: 0.15 | F49: 0.2 | G49: 0.2 | H49: 0.25 | I49: 0.3 | J49: 0.3 | K49: 0.25 | L49: 0.2 | M49: 0.15 | N49: 0.1
...

Sheet IRRIGATION
B4: Besoins en eau = consommation en eau – disponibilités en eau
B5: ETR = ETP x Kc
B7: Coefficient cultural | C7: Janvier à fin février | D7: 1er mars au 31 mars | E7: 1er avril au 15 mai | F7: 15 mai au 31 juillet | G7: 1er août au 15 septembre | H7: 15 septembre au 30 septembre | I7: 1er octobre au 30 octobre | J7: 1er novembre au 15 novembre | K7: 15 novembre à fin décembre
B8: Kc | C8: 0.1 | D8: 0.15 | E8: 0.2 | F8: 0.25 | G8: 0.3 | H8: 0.25 | I8: 0.2 | J8: 0.15 | K8: 0.1
C12: Janvier | D12: Fevrier | E12: Mars | F12: Avril | G12: Mai | H12: Juin | I12: Juillet | J12: Août | K12: Septembre | L12: Octobre | M12: Novembre | N12: Decembre
B13: NOMBRE DE JOURS | C13: 31 | D13: 28 | E13: 31 | F13: 30 | G13: 31 | H13: 30 | I13: 31 | J13: 31 | K13: 30 | L13: 31 | M13: 30 | N13: 31
B14: ET0 JOURS mm | C14: ='BESOIN EN EAU'!C5 -> 2.0903226 | D14: ='BESOIN EN EAU'!D5 -> 1.85 | E14: ='BESOIN EN EAU'!E5 -> 2.4322581 | F14: ='BESOIN EN EAU'!F5 -> 3.2933333 | G14: ='BESOIN EN EAU'!G5 -> 4.683871 | H14: ='BESOIN EN EAU'!H5 -> 5.9733333 | I14: ='BESOIN EN EAU'!I5 -> 7.4677419 | J14: ='BESOIN EN EAU'!J5 -> 7.516129 | ... N14: ='BESOIN EN EAU'!N5 -> 1.5774194
B15: ET0 JOURS m3/ha | C15: =C14*10 -> 20.903226 | D15: =D14*10 -> 18.5 | E15: =E14*10 -> 24.322581 | F15: =F14*10 -> 32.933333 | G15: =G14*10 -> 46.83871 | H15: =H14*10 -> 59.733333 | I15: =I14*10 -> 74.677419 | J15: =J14*10 -> 75.16129 | ... N15: =N14*10 -> 15.774194
B16: ET0 MOIS mm | C16: =C14*C13 -> 64.8 | D16: =D14*D13 -> 51.8 | E16: =E14*E13 -> 75.4 | F16: =F14*F13 -> 98.8 | G16: =G14*G13 -> 145.2 | H16: =H14*H13 -> 179.2 | I16: =I14*I13 -> 231.5 | J16: =J14*J13 -> 233 | ... N16: =N14*N13 -> 48.9
B17: ET0 MOIS m3/ha | C17: =C16*10 -> 648 | D17: =D16*10 -> 518 | E17: =E16*10 -> 754 | F17: =F16*10 -> 988 | G17: =G16*10 -> 1452 | H17: =H16*10 -> 1792 | I17: =I16*10 -> 2315 | J17: =J16*10 -> 2330 | ... N17: =N16*10 -> 489
B19: Kc | C19: ='BESOIN EN EAU'!C10 -> 0.3 | D19: ='BESOIN EN EAU'!D10 -> 0.4 | E19: ='BESOIN EN EAU'!E10 -> 0.4 | F19: ='BESOIN EN EAU'!F10 -> 0.5 | G19: ='BESOIN EN EAU'!G10 -> 0.8 | H19: ='BESOIN EN EAU'!H10 -> 1 | I19: ='BESOIN EN EAU'!I10 -> 1.05 | J19: ='BESOIN EN EAU'!J10 -> 1.05 | ... N19: ='BESOIN EN EAU'!N10 -> 0.8
B20: Kr | C20: ='BESOIN EN EAU'!C11 -> 0.7 | D20: ='BESOIN EN EAU'!D11 -> 0.7 | E20: ='BESOIN EN EAU'!E11 -> 0.7 | F20: ='BESOIN EN EAU'!F11 -> 0.7 | G20: ='BESOIN EN EAU'!G11 -> 0.7 | H20: ='BESOIN EN EAU'!H11 -> 0.7 | I20: ='BESOIN EN EAU'!I11 -> 0.7 | J20: ='BESOIN EN EAU'!J11 -> 0.7 | ... N20: ='BESOIN EN EAU'!N11 -> 0.7
B21: Superficie | C21: ='BESOIN EN EAU'!C16 -> 5 | D21: ='BESOIN EN EAU'!D16 -> 5 | E21: ='BESOIN EN EAU'!E16 -> 5 | F21: ='BESOIN EN EAU'!F16 -> 5 | G21: ='BESOIN EN EAU'!G16 -> 5 | H21: ='BESOIN EN EAU'!H16 -> 5 | I21: ='BESOIN EN EAU'!I16 -> 5 | J21: ='BESOIN EN EAU'!J16 -> 5 | ... N21: ='BESOIN EN EAU'!N16 -> 5
B22: EFFICIENCE Ea=90% | C22: 0.9 | D22: 0.9 | E22: 0.9 | F22: 0.9 | G22: 0.9 | H22: 0.9 | I22: 0.9 | J22: 0.9 | K22: 0.9 | L22: 0.9 | M22: 0.9 | N22: 0.9
B23: Be Brut (m3)/ha | C23: =(C17*C19*C20*C21)/C22 -> 756 | D23: =(D17*D19*D20*D21)/D22 -> 805.77778 | E23: =(E17*E19*E20*E21)/E22 -> 1172.8889 | F23: =(F17*F19*F20*F21)/F22 -> 1921.1111 | G23: =(G17*G19*G20*G21)/G22 -> 4517.3333 | H23: =(H17*H19*H20*H21)/H22 -> 6968.8889 | I23: =(I17*I19*I20*I21)/I22 -> 9452.9167 | J23: =(J17*J19*J20*J21)/J22 -> 9514.1667 | ... N23: =(N17*N19*N20*N21)/N22 -> 1521.3333 | O23: =SUM(C23:N23) -> 50812.028
B24: Be Brut (mm)/mois | C24: =C23/10 -> 75.6 | D24: =D23/10 -> 80.577778 | E24: =E23/10 -> 117.28889 | F24: =F23/10 -> 192.11111 | G24: =G23/10 -> 451.73333 | H24: =H23/10 -> 696.88889 | I24: =I23/10 -> 945.29167 | J24: =J23/10 -> 951.41667 | ... N24: =N23/10 -> 152.13333
B25: Be Brut (mm)/jours | C25: =C24/C13 -> 2.4387097 | D25: =D24/D13 -> 2.8777778 | E25: =E24/E13 -> 3.7835125 | F25: =F24/F13 -> 6.4037037 | G25: =G24/G13 -> 14.572043 | H25: =H24/H13 -> 23.22963 | I25: =I24/I13 -> 30.49328 | J25: =J24/J13 -> 30.69086 | ... N25: =N24/N13 -> 4.9075269
B29: Dose d’irrigation
B31: Equivalences : 1 mm = 10 m3/ha = 1 L/m2
B33: Dose (en litres/arbre) = Dose (en mm) x Surface occupée par l’olivier (en m2)
C34: Janvier | D34: Fevrier | E34: Mars | F34: Avril | G34: Mai | H34: Juin | I34: Juillet | J34: Août | K34: Septembre | L34: Octobre | M34: Novembre | N34: Decembre
B35: Eg | C35: 6 | D35: =C35 -> 6 | E35: =D35 -> 6 | F35: =E35 -> 6 | G35: =F35 -> 6 | H35: =G35 -> 6 | I35: =H35 -> 6 | J35: =I35 -> 6 | K35: =J35 -> 6 | ... N35: =M35 -> 6
B36: Er | C36: 6 | D36: =C36 -> 6 | E36: =D36 -> 6 | F36: =E36 -> 6 | G36: =F36 -> 6 | H36: =G36 -> 6 | I36: =H36 -> 6 | J36: =I36 -> 6 | K36: =J36 -> 6 | ... N36: =M36 -> 6
B37: ETR | C37: =C25 -> 2.4387097 | D37: =D25 -> 2.8777778 | E37: =E25 -> 3.7835125 | F37: =F25 -> 6.4037037 | G37: =G25 -> 14.572043 | H37: =H25 -> 23.22963 | I37: =I25 -> 30.49328 | J37: =J25 -> 30.69086 | ... N37: =N25 -> 4.9075269
B38: Dose (en l/arbre) | C38: =C37*C36*C35 -> 87.793548 | D38: =D37*D36*D35 -> 103.6 | E38: =E37*E36*E35 -> 136.20645 | F38: =F37*F36*F35 -> 230.53333 | G38: =G37*G36*G35 -> 524.59355 | H38: =H37*H36*H35 -> 836.26667 | I38: =I37*I36*I35 -> 1097.7581 | J38: =J37*J36*J35 -> 1104.871 | ... N38: =N37*N36*N35 -> 176.67097
B40: Durée de l’irrigation
B42: Durée (en heure) = Dose (en litres/arbre) / Débit par arbre (en litres/heure)
C43: Janvier | D43: Fevrier | E43: Mars | F43: Avril | G43: Mai | H43: Juin | I43: Juillet | J43: Août | K43: Septembre | L43: Octobre | M43: Novembre | N43: Decembre
B44: Nombre de gouteur | C44: 2 | D44: =C44 -> 2 | E44: =D44 -> 2 | F44: =E44 -> 2 | G44: =F44 -> 2 | H44: =G44 -> 2 | I44: =H44 -> 2 | J44: =I44 -> 2 | K44: =J44 -> 2 | ... N44: =M44 -> 2
B45: Débit GG (l/heure) | C45: 16 | D45: =C45 -> 16 | E45: =D45 -> 16 | F45: =E45 -> 16 | G45: =F45 -> 16 | H45: =G45 -> 16 | I45: =H45 -> 16 | J45: =I45 -> 16 | K45: =J45 -> 16 | ... N45: =M45 -> 16
B46: Débit par arbre (l/heure) | C46: =C45*C44 -> 32 | D46: =D45*D44 -> 32 | E46: =E45*E44 -> 32 | F46: =F45*F44 -> 32 | G46: =G45*G44 -> 32 | H46: =H45*H44 -> 32 | I46: =I45*I44 -> 32 | J46: =J45*J44 -> 32 | ... N46: =N45*N44 -> 32
B47: Durée (en heure) | C47: =C38/C46 -> 2.7435484 | D47: =D38/D46 -> 3.2375 | E47: =E38/E46 -> 4.2564516 | F47: =F38/F46 -> 7.2041667 | G47: =G38/G46 -> 16.393548 | H47: =H38/H46 -> 26.133333 | I47: =I38/I46 -> 34.30494 | J47: =J38/J46 -> 34.527218 | ... N47: =N38/N46 -> 5.5209677
B50: Poste d’irrigation
B52: Surface du poste (en hectare) = Débit à la source (en m3/heure) / Débit par hectare (en m3/hectare)
B54: Nombre de gouteur | C54: 2
B55: Débit GG (l/heure) | C55: 16
B56: Débit par arbre (l/heure) | C56: 16
B57: Nombre d’arbres par hectare | C57: =10000/(C36*C35) -> 277.77778
B58: Débit par hectare | C58: l/h/ha | D58: m3/h/ha
C59: =C57*C56 -> 4444.4444 | D59: =C59/1000 -> 4.4444444
...

Sheet DIMENSIONNEMENT
D6: LONGUEUR DE CANALISATION
D7: PRESSION
